Workbook

Sheet IBM_Telecom_Customer_Churn_Anal
A1: customerID | B1: gender | C1: SeniorCitizen | D1: Partner | E1: Dependents | F1: tenure | G1: PhoneService | H1: MultipleLines | I1: InternetService | J1: OnlineSecurity | K1: OnlineBackup | L1: DeviceProtection | M1: TechSupport | N1: StreamingTV | O1: StreamingMovies | P1: Contract | Q1: PaperlessBilling | R1: PaymentMethod | S1: MonthlyCharges | T1: TotalCharges | U1: Churn | V1: TenureGroup | W1: Monthly Charge Group | X1: Service Count
A2: 7590-VHVEG | B2: Female | C2: 0 | D2: Yes | E2: No | F2: 1 | G2: No | H2: No phone service | I2: DSL | J2: No | K2: Yes | L2: No | M2: No | N2: No | O2: No | P2: Month-to-month | Q2: Yes | R2: Electronic check | S2: 29.85 | T2: 29.85 | U2: No | V2: =IF(F2<=12,"0-12 Months",IF(F2<=24,"13-24 Months",IF(F2<=48,"25-48 Months","49-72 Months"))) -> 0-12 Months | W2: =IF(S2<=30,"0-30",IF(S2<=60,"31-60",IF(S2<=90,"61-90","91+"))) -> 0-30 | X2: =COUNTIF(G2:O2,"Yes") -> 1
A3: 5575-GNVDE | B3: Male | C3: 0 | D3: No | E3: No | F3: 34 | G3: Yes | H3: No | I3: DSL | J3: Yes | K3: No | L3: Yes | M3: No | N3: No | O3: No | P3: One year | Q3: No | R3: Mailed check | S3: 56.95 | T3: 1889.5 | U3: No | V3: =IF(F3<=12,"0-12 Months",IF(F3<=24,"13-24 Months",IF(F3<=48,"25-48 Months","49-72 Months"))) -> 25-48 Months | W3: =IF(S3<=30,"0-30",IF(S3<=60,"31-60",IF(S3<=90,"61-90","91+"))) -> 31-60 | X3: =COUNTIF(G3:O3,"Yes") -> 3
A4: 3668-QPYBK | B4: Male | C4: 0 | D4: No | E4: No | F4: 2 | G4: Yes | H4: No | I4: DSL | J4: Yes | K4: Yes | L4: No | M4: No | N4: No | O4: No | P4: Month-to-month | Q4: Yes | R4: Mailed check | S4: 53.85 | T4: 108.15 | U4: Yes | V4: =IF(F4<=12,"0-12 Months",IF(F4<=24,"13-24 Months",IF(F4<=48,"25-48 Months","49-72 Months"))) -> 0-12 Months | W4: =IF(S4<=30,"0-30",IF(S4<=60,"31-60",IF(S4<=90,"61-90","91+"))) -> 31-60 | X4: =COUNTIF(G4:O4,"Yes") -> 3
A5: 7795-CFOCW | B5: Male | C5: 0 | D5: No | E5: No | F5: 45 | G5: No | H5: No phone service | I5: DSL | J5: Yes | K5: No | L5: Yes | M5: Yes | N5: No | O5: No | P5: One year | Q5: No | R5: Bank transfer (automatic) | S5: 42.3 | T5: 1840.75 | U5: No | V5: =IF(F5<=12,"0-12 Months",IF(F5<=24,"13-24 Months",IF(F5<=48,"25-48 Months","49-72 Months"))) -> 25-48 Months | W5: =IF(S5<=30,"0-30",IF(S5<=60,"31-60",IF(S5<=90,"61-90","91+"))) -> 31-60 | X5: =COUNTIF(G5:O5,"Yes") -> 3
A6: 9237-HQITU | B6: Female | C6: 0 | D6: No | E6: No | F6: 2 | G6: Yes | H6: No | I6: Fiber optic | J6: No | K6: No | L6: No | M6: No | N6: No | O6: No | P6: Month-to-month | Q6: Yes | R6: Electronic check | S6: 70.7 | T6: 151.65 | U6: Yes | V6: =IF(F6<=12,"0-12 Months",IF(F6<=24,"13-24 Months",IF(F6<=48,"25-48 Months","49-72 Months"))) -> 0-12 Months | W6: =IF(S6<=30,"0-30",IF(S6<=60,"31-60",IF(S6<=90,"61-90","91+"))) -> 61-90 | X6: =COUNTIF(G6:O6,"Yes") -> 1
A7: 9305-CDSKC | B7: Female | C7: 0 | D7: No | E7: No | F7: 8 | G7: Yes | H7: Yes | I7: Fiber optic | J7: No | K7: No | L7: Yes | M7: No | N7: Yes | O7: Yes | P7: Month-to-month | Q7: Yes | R7: Electronic check | S7: 99.65 | T7: 820.5 | U7: Yes | V7: =IF(F7<=12,"0-12 Months",IF(F7<=24,"13-24 Months",IF(F7<=48,"25-48 Months","49-72 Months"))) -> 0-12 Months | W7: =IF(S7<=30,"0-30",IF(S7<=60,"31-60",IF(S7<=90,"61-90","91+"))) -> 91+ | X7: =COUNTIF(G7:O7,"Yes") -> 5
A8: 1452-KIOVK | B8: Male | C8: 0 | D8: No | E8: Yes | F8: 22 | G8: Yes | H8: Yes | I8: Fiber optic | J8: No | K8: Yes | L8: No | M8: No | N8: Yes | O8: No | P8: Month-to-month | Q8: Yes | R8: Credit card (automatic) | S8: 89.1 | T8: 1949.4 | U8: No | V8: =IF(F8<=12,"0-12 Months",IF(F8<=24,"13-24 Months",IF(F8<=48,"25-48 Months","49-72 Months"))) -> 13-24 Months | W8: =IF(S8<=30,"0-30",IF(S8<=60,"31-60",IF(S8<=90,"61-90","91+"))) -> 61-90 | X8: =COUNTIF(G8:O8,"Yes") -> 4
A9: 6713-OKOMC | B9: Female | C9: 0 | D9: No | E9: No | F9: 10 | G9: No | H9: No phone service | I9: DSL | J9: Yes | K9: No | L9: No | M9: No | N9: No | O9: No | P9: Month-to-month | Q9: No | R9: Mailed check | S9: 29.75 | T9: 301.9 | U9: No | V9: =IF(F9<=12,"0-12 Months",IF(F9<=24,"13-24 Months",IF(F9<=48,"25-48 Months","49-72 Months"))) -> 0-12 Months | W9: =IF(S9<=30,"0-30",IF(S9<=60,"31-60",IF(S9<=90,"61-90","91+"))) -> 0-30 | X9: =COUNTIF(G9:O9,"Yes") -> 1
A10: 7892-POOKP | B10: Female | C10: 0 | D10: Yes | E10: No | F10: 28 | G10: Yes | H10: Yes | I10: Fiber optic | J10: No | K10: No | L10: Yes | M10: Yes | N10: Yes | O10: Yes | P10: Month-to-month | Q10: Yes | R10: Electronic check | S10: 104.8 | T10: 3046.05 | U10: Yes | V10: =IF(F10<=12,"0-12 Months",IF(F10<=24,"13-24 Months",IF(F10<=48,"25-48 Months","49-72 Months"))) -> 25-48 Months | W10: =IF(S10<=30,"0-30",IF(S10<=60,"31-60",IF(S10<=90,"61-90","91+"))) -> 91+ | X10: =COUNTIF(G10:O10,"Yes") -> 6
A11: 6388-TABGU | B11: Male | C11: 0 | D11: No | E11: Yes | F11: 62 | G11: Yes | H11: No | I11: DSL | J11: Yes | K11: Yes | L11: No | M11: No | N11: No | O11: No | P11: One year | Q11: No | R11: Bank transfer (automatic) | S11: 56.15 | T11: 3487.95 | U11: No | V11: =IF(F11<=12,"0-12 Months",IF(F11<=24,"13-24 Months",IF(F11<=48,"25-48 Months","49-72 Months"))) -> 49-72 Months | W11: =IF(S11<=30,"0-30",IF(S11<=60,"31-60",IF(S11<=90,"61-90","91+"))) -> 31-60 | X11: =COUNTIF(G11:O11,"Yes") -> 3
A12: 9763-GRSKD | B12: Male | C12: 0 | D12: Yes | E12: Yes | F12: 13 | G12: Yes | H12: No | I12: DSL | J12: Yes | K12: No | L12: No | M12: No | N12: No | O12: No | P12: Month-to-month | Q12: Yes | R12: Mailed check | S12: 49.95 | T12: 587.45 | U12: No | V12: =IF(F12<=12,"0-12 Months",IF(F12<=24,"13-24 Months",IF(F12<=48,"25-48 Months","49-72 Months"))) -> 13-24 Months | W12: =IF(S12<=30,"0-30",IF(S12<=60,"31-60",IF(S12<=90,"61-90","91+"))) -> 31-60 | X12: =COUNTIF(G12:O12,"Yes") -> 2
A13: 7469-LKBCI | B13: Male | C13: 0 | D13: No | E13: No | F13: 16 | G13: Yes | H13: No | I13: No | J13: No internet service | K13: No internet service | L13: No internet service | M13: No internet service | N13: No internet service | O13: No internet service | P13: Two year | Q13: No | R13: Credit card (automatic) | S13: 18.95 | T13: 326.8 | U13: No | V13: =IF(F13<=12,"0-12 Months",IF(F13<=24,"13-24 Months",IF(F13<=48,"25-48 Months","49-72 Months"))) -> 13-24 Months | W13: =IF(S13<=30,"0-30",IF(S13<=60,"31-60",IF(S13<=90,"61-90","91+"))) -> 0-30 | X13: =COUNTIF(G13:O13,"Yes") -> 1
... A489: 3649-JPUGY | B489: Male | C489: 0 | D489: No | E489: No | F489: 72 | G489: Yes | H489: Yes | I489: DSL | J489: No | K489: Yes | L489: Yes | M489: Yes | N489: Yes | O489: Yes | P489: Two year | Q489: Yes | R489: Bank transfer (automatic) | S489: 88.6 | T489: 6201.95 | U489: No | V489: =IF(F489<=12,"0-12 Months",IF(F489<=24,"13-24 Months",IF(F489<=48,"25-48 Months","49-72 Months"))) -> 49-72 Months | W489: =IF(S489<=30,"0-30",IF(S489<=60,"31-60",IF(S489<=90,"61-90","91+"))) -> 61-90 | X489: =COUNTIF(G489:O489,"Yes") -> 7
A490: 4472-LVYGI | B490: Female | C490: 0 | D490: Yes | E490: Yes | F490: 0 | G490: No | H490: No phone service | I490: DSL | J490: Yes | K490: No | L490: Yes | M490: Yes | N490: Yes | O490: No | P490: Two year | Q490: Yes | R490: Bank transfer (automatic) | S490: 52.55 | U490: No | V490: =IF(F490<=12,"0-12 Months",IF(F490<=24,"13-24 Months",IF(F490<=48,"25-48 Months","49-72 Months"))) -> 0-12 Months | W490: =IF(S490<=30,"0-30",IF(S490<=60,"31-60",IF(S490<=90,"61-90","91+"))) -> 31-60 | X490: =COUNTIF(G490:O490,"Yes") -> 4
A491: 8372-JUXUI | B491: Male | C491: 0 | D491: No | E491: Yes | F491: 1 | G491: Yes | H491: Yes | I491: Fiber optic | J491: No | K491: No | L491: No | M491: No | N491: No | O491: No | P491: Month-to-month | Q491: Yes | R491: Electronic check | S491: 74.35 | T491: 74.35 | U491: Yes | V491: =IF(F491<=12,"0-12 Months",IF(F491<=24,"13-24 Months",IF(F491<=48,"25-48 Months","49-72 Months"))) -> 0-12 Months | W491: =IF(S491<=30,"0-30",IF(S491<=60,"31-60",IF(S491<=90,"61-90","91+"))) -> 61-90 | X491: =COUNTIF(G491:O491,"Yes") -> 2
A492: 3552-CTCYF | B492: Male | C492: 0 | D492: Yes | E492: Yes | F492: 63 | G492: Yes | H492: Yes | I492: Fiber optic | J492: No | K492: Yes | L492: Yes | M492: No | N492: Yes | O492: Yes | P492: Two year | Q492: Yes | R492: Bank transfer (automatic) | S492: 104.8 | T492: 6597.25 | U492: No | V492: =IF(F492<=12,"0-12 Months",IF(F492<=24,"13-24 Months",IF(F492<=48,"25-48 Months","49-72 Months"))) -> 49-72 Months | W492: =IF(S492<=30,"0-30",IF(S492<=60,"31-60",IF(S492<=90,"61-90","91+"))) -> 91+ | X492: =COUNTIF(G492:O492,"Yes") -> 6
A493: 6778-YSNIH | B493: Female | C493: 0 | D493: No | E493: No | F493: 2 | G493: Yes | H493: No | I493: DSL | J493: No | K493: Yes | L493: No | M493: No | N493: Yes | O493: No | P493: Month-to-month | Q493: Yes | R493: Electronic check | S493: 59 | T493: 114.15 | U493: No | V493: =IF(F493<=12,"0-12 Months",IF(F493<=24,"13-24 Months",IF(F493<=48,"25-48 Months","49-72 Months"))) -> 0-12 Months | W493: =IF(S493<=30,"0-30",IF(S493<=60,"31-60",IF(S493<=90,"61-90","91+"))) -> 31-60 | X493: =COUNTIF(G493:O493,"Yes") -> 3
A494: 0388-EOPEX | B494: Female | C494: 0 | D494: Yes | E494: No | F494: 2 | G494: Yes | H494: No | I494: Fiber optic | J494: Yes | K494: No | L494: No | M494: No | N494: No | O494: No | P494: Month-to-month | Q494: Yes | R494: Electronic check | S494: 74.4 | T494: 139.4 | U494: Yes | V494: =IF(F494<=12,"0-12 Months",IF(F494<=24,"13-24 Months",IF(F494<=48,"25-48 Months","49-72 Months"))) -> 0-12 Months | W494: =IF(S494<=30,"0-30",IF(S494<=60,"31-60",IF(S494<=90,"61-90","91+"))) -> 61-90 | X494: =COUNTIF(G494:O494,"Yes") -> 2
A495: 5756-OZRIO | B495: Male | C495: 1 | D495: Yes | E495: No | F495: 61 | G495: Yes | H495: Yes | I495: DSL | J495: No | K495: Yes | L495: No | M495: No | N495: No | O495: Yes | P495: One year | Q495: No | R495: Bank transfer (automatic) | S495: 64.05 | T495: 3902.6 | U495: No | V495: =IF(F495<=12,"0-12 Months",IF(F495<=24,"13-24 Months",IF(F495<=48,"25-48 Months","49-72 Months"))) -> 49-72 Months | W495: =IF(S495<=30,"0-30",IF(S495<=60,"31-60",IF(S495<=90,"61-90","91+"))) -> 61-90 | X495: =COUNTIF(G495:O495,"Yes") -> 4
A496: 6579-JPICP | B496: Male | C496: 0 | D496: No | E496: No | F496: 1 | G496: Yes | H496: No | I496: No | J496: No internet service | K496: No internet service | L496: No internet service | M496: No internet service | N496: No internet service | O496: No internet service | P496: Month-to-month | Q496: No | R496: Mailed check | S496: 20.4 | T496: 20.4 | U496: No | V496: =IF(F496<=12,"0-12 Months",IF(F496<=24,"13-24 Months",IF(F496<=48,"25-48 Months","49-72 Months"))) -> 0-12 Months | W496: =IF(S496<=30,"0-30",IF(S496<=60,"31-60",IF(S496<=90,"61-90","91+"))) -> 0-30 | X496: =COUNTIF(G496:O496,"Yes") -> 1
A497: 8205-OTCHB | B497: Male | C497: 0 | D497: No | E497: No | F497: 22 | G497: No | H497: No phone service | I497: DSL | J497: No | K497: Yes | L497: Yes | M497: No | N497: No | O497: Yes | P497: One year | Q497: Yes | R497: Bank transfer (automatic) | S497: 43.75 | T497: 903.6 | U497: Yes | V497: =IF(F497<=12,"0-12 Months",IF(F497<=24,"13-24 Months",IF(F497<=48,"25-48 Months","49-72 Months"))) -> 13-24 Months | W497: =IF(S497<=30,"0-30",IF(S497<=60,"31-60",IF(S497<=90,"61-90","91+"))) -> 31-60 | X497: =COUNTIF(G497:O497,"Yes") -> 3
A498: 4134-BSXLX | B498: Male | C498: 0 | D498: Yes | E498: No | F498: 28 | G498: Yes | H498: No | I498: DSL | J498: Yes | K498: Yes | L498: No | M498: Yes | N498: No | O498: No | P498: Month-to-month | Q498: No | R498: Mailed check | S498: 60.9 | T498: 1785.65 | U498: No | V498: =IF(F498<=12,"0-12 Months",IF(F498<=24,"13-24 Months",IF(F498<=48,"25-48 Months","49-72 Months"))) -> 25-48 Months | W498: =IF(S498<=30,"0-30",IF(S498<=60,"31-60",IF(S498<=90,"61-90","91+"))) -> 61-90 | X498: =COUNTIF(G498:O498,"Yes") -> 4
A499: 0505-SPOOW | B499: Female | C499: 0 | D499: Yes | E499: No | F499: 70 | G499: Yes | H499: No | I499: No | J499: No internet service | K499: No internet service | L499: No internet service | M499: No internet service | N499: No internet service | O499: No internet service | P499: Two year | Q499: No | R499: Bank transfer (automatic) | S499: 19.8 | T499: 1397.65 | U499: No | V499: =IF(F499<=12,"0-12 Months",IF(F499<=24,"13-24 Months",IF(F499<=48,"25-48 Months","49-72 Months"))) -> 49-72 Months | W499: =IF(S499<=30,"0-30",IF(S499<=60,"31-60",IF(S499<=90,"61-90","91+"))) -> 0-30 | X499: =COUNTIF(G499:O499,"Yes") -> 1
A500: 6235-VDHOM | B500: Female | C500: 1 | D500: No | E500: No | F500: 5 | G500: No | H500: No phone service | I500: DSL | J500: No | K500: Yes | L500: No | M500: No | N500: No | O500: No | P500: Month-to-month | Q500: No | R500: Electronic check | S500: 28.45 | T500: 131.05 | U500: Yes | V500: =IF(F500<=12,"0-12 Months",IF(F500<=24,"13-24 Months",IF(F500<=48,"25-48 Months","49-72 Months"))) -> 0-12 Months | W500: =IF(S500<=30,"0-30",IF(S500<=60,"31-60",IF(S500<=90,"61-90","91+"))) -> 0-30 | X500: =COUNTIF(G500:O500,"Yes") -> 1
A501: 7783-YKGDV | B501: Female | C501: 0 | D501: No | E501: No | F501: 12 | G501: Yes | H501: Yes | I501: Fiber optic | J501: Yes | K501: Yes | L501: Yes | M501: No | N501: No | O501: Yes | P501: Month-to-month | Q501: Yes | R501: Bank transfer (automatic) | S501: 99.7 | T501: 1238.45 | U501: Yes | V501: =IF(F501<=12,"0-12 Months",IF(F501<=24,"13-24 Months",IF(F501<=48,"25-48 Months","49-72 Months"))) -> 0-12 Months | W501: =IF(S501<=30,"0-30",IF(S501<=60,"31-60",IF(S501<=90,"61-90","91+"))) -> 91+ | X501: =COUNTIF(G501:O501,"Yes") -> 6
A502: 4374-YMUSQ | B502: Male | C502: 0 | D502: No | E502: No | F502: 34 | G502: Yes | H502: Yes | I502: Fiber optic | J502: Yes | K502: Yes | L502: Yes | M502: Yes | N502: Yes | O502: Yes | P502: One year | Q502: No | R502: Credit card (automatic) | S502: 116.25 | T502: 3899.05 | U502: No | V502: =IF(F502<=12,"0-12 Months",IF(F502<=24,"13-24 Months",IF(F502<=48,"25-48 Months","49-72 Months"))) -> 25-48 Months | W502: =IF(S502<=30,"0-30",IF(S502<=60,"31-60",IF(S502<=90,"61-90","91+"))) -> 91+ | X502: =COUNTIF(G502:O502,"Yes") -> 8
... A754: 1410-RSCMR | B754: Male | C754: 0 | D754: Yes | E754: Yes | F754: 7 | G754: Yes | H754: No | I754: DSL | J754: Yes | K754: No | L754: Yes | M754: Yes | N754: No | O754: Yes | P754: Month-to-month | Q754: Yes | R754: Credit card (automatic) | S754: 71.35 | T754: 515.75 | U754: No | V754: =IF(F754<=12,"0-12 Months",IF(F754<=24,"13-24 Months",IF(F754<=48,"25-48 Months","49-72 Months"))) -> 0-12 Months | W754: =IF(S754<=30,"0-30",IF(S754<=60,"31-60",IF(S754<=90,"61-90","91+"))) -> 61-90 | X754: =COUNTIF(G754:O754,"Yes") -> 5
A755: 3115-CZMZD | B755: Male | C755: 0 | D755: No | E755: Yes | F755: 0 | G755: Yes | H755: No | I755: No | J755: No internet service | K755: No internet service | L755: No internet service | M755: No internet service | N755: No internet service | O755: No internet service | P755: Two year | Q755: No | R755: Mailed check | S755: 20.25 | U755: No | V755: =IF(F755<=12,"0-12 Months",IF(F755<=24,"13-24 Months",IF(F755<=48,"25-48 Months","49-72 Months"))) -> 0-12 Months | W755: =IF(S755<=30,"0-30",IF(S755<=60,"31-60",IF(S755<=90,"61-90","91+"))) -> 0-30 | X755: =COUNTIF(G755:O755,"Yes") -> 1
A756: 0139-IVFJG | B756: Female | C756: 0 | D756: Yes | E756: No | F756: 2 | G756: Yes | H756: No | I756: Fiber optic | J756: Yes | K756: Yes | L756: No | M756: No | N756: Yes | O756: No | P756: Month-to-month | Q756: No | R756: Electronic check | S756: 90.35 | T756: 190.5 | U756: No | V756: =IF(F756<=12,"0-12 Months",IF(F756<=24,"13-24 Months",IF(F756<=48,"25-48 Months","49-72 Months"))) -> 0-12 Months | W756: =IF(S756<=30,"0-30",IF(S756<=60,"31-60",IF(S756<=90,"61-90","91+"))) -> 91+ | X756: =COUNTIF(G756:O756,"Yes") -> 4
A757: 6683-VLCTZ | B757: Male | C757: 1 | D757: No | E757: No | F757: 20 | G757: Yes | H757: Yes | I757: Fiber optic | J757: No | K757: No | L757: Yes | M757: No | N757: Yes | O757: Yes | P757: Month-to-month | Q757: Yes | R757: Electronic check | S757: 98.55 | T757: 1842.8 | U757: Yes | V757: =IF(F757<=12,"0-12 Months",IF(F757<=24,"13-24 Months",IF(F757<=48,"25-48 Months","49-72 Months"))) -> 13-24 Months | W757: =IF(S757<=30,"0-30",IF(S757<=60,"31-60",IF(S757<=90,"61-90","91+"))) -> 91+ | X757: =COUNTIF(G757:O757,"Yes") -> 5
A758: 5730-DBDSI | B758: Male | C758: 0 | D758: No | E758: No | F758: 66 | G758: Yes | H758: No | I758: No | J758: No internet service | K758: No internet service | L758: No internet service | M758: No internet service | N758: No internet service | O758: No internet service | P758: Two year | Q758: No | R758: Bank transfer (automatic) | S758: 19.7 | T758: 1253.8 | U758: No | V758: =IF(F758<=12,"0-12 Months",IF(F758<=24,"13-24 Months",IF(F758<=48,"25-48 Months","49-72 Months"))) -> 49-72 Months | W758: =IF(S758<=30,"0-30",IF(S758<=60,"31-60",IF(S758<=90,"61-90","91+"))) -> 0-30 | X758: =COUNTIF(G758:O758,"Yes") -> 1
A759: 0030-FNXPP | B759: Female | C759: 0 | D759: No | E759: No | F759: 3 | G759: Yes | H759: No | I759: No | J759: No internet service | K759: No internet service | L759: No internet service | M759: No internet service | N759: No internet service | O759: No internet service | P759: Month-to-month | Q759: No | R759: Mailed check | S759: 19.85 | T759: 57.2 | U759: No | V759: =IF(F759<=12,"0-12 Months",IF(F759<=24,"13-24 Months",IF(F759<=48,"25-48 Months","49-72 Months"))) -> 0-12 Months | W759: =IF(S759<=30,"0-30",IF(S759<=60,"31-60",IF(S759<=90,"61-90","91+"))) -> 0-30 | X759: =COUNTIF(G759:O759,"Yes") -> 1
A760: 2189-WWOEW | B760: Female | C760: 0 | D760: No | E760: Yes | F760: 15 | G760: Yes | H760: No | I760: Fiber optic | J760: No | K760: Yes | L760: No | M760: No | N760: No | O760: Yes | P760: Month-to-month | Q760: Yes | R760: Bank transfer (automatic) | S760: 85.9 | T760: 1269.55 | U760: Yes | V760: =IF(F760<=12,"0-12 Months",IF(F760<=24,"13-24 Months",IF(F760<=48,"25-48 Months","49-72 Months"))) -> 13-24 Months | W760: =IF(S760<=30,"0-30",IF(S760<=60,"31-60",IF(S760<=90,"61-90","91+"))) -> 61-90 | X760: =COUNTIF(G760:O760,"Yes") -> 3
A761: 5684-FJVYR | B761: Female | C761: 0 | D761: Yes | E761: Yes | F761: 72 | G761: Yes | H761: Yes | I761: Fiber optic | J761: Yes | K761: Yes | L761: No | M761: Yes | N761: No | O761: No | P761: Two year | Q761: Yes | R761: Bank transfer (automatic) | S761: 90.35 | T761: 6563.4 | U761: No | V761: =IF(F761<=12,"0-12 Months",IF(F761<=24,"13-24 Months",IF(F761<=48,"25-48 Months","49-72 Months"))) -> 49-72 Months | W761: =IF(S761<=30,"0-30",IF(S761<=60,"31-60",IF(S761<=90,"61-90","91+"))) -> 91+ | X761: =COUNTIF(G761:O761,"Yes") -> 5
A762: 4013-GUXND | B762: Male | C762: 0 | D762: No | E762: No | F762: 1 | G762: Yes | H762: No | I762: No | J762: No internet service | K762: No internet service | L762: No internet service | M762: No internet service | N762: No internet service | O762: No internet service | P762: Month-to-month | Q762: No | R762: Mailed check | S762: 20.8 | T762: 20.8 | U762: No | V762: =IF(F762<=12,"0-12 Months",IF(F762<=24,"13-24 Months",IF(F762<=48,"25-48 Months","49-72 Months"))) -> 0-12 Months | W762: =IF(S762<=30,"0-30",IF(S762<=60,"31-60",IF(S762<=90,"61-90","91+"))) -> 0-30 | X762: =COUNTIF(G762:O762,"Yes") -> 1
A763: 1894-IGFSG | B763: Female | C763: 0 | D763: No | E763: No | F763: 22 | G763: Yes | H763: No | I763: Fiber optic | J763: No | K763: No | L763: No | M763: No | N763: Yes | O763: Yes | P763: Month-to-month | Q763: No | R763: Electronic check | S763: 89.25 | T763: 1907.85 | U763: Yes | V763: =IF(F763<=12,"0-12 Months",IF(F763<=24,"13-24 Months",IF(F763<=48,"25-48 Months","49-72 Months"))) -> 13-24 Months | W763: =IF(S763<=30,"0-30",IF(S763<=60,"31-60",IF(S763<=90,"61-90","91+"))) -> 61-90 | X763: =COUNTIF(G763:O763,"Yes") -> 3
A764: 7379-POKDZ | B764: Male | C764: 0 | D764: Yes | E764: No | F764: 3 | G764: Yes | H764: No | I764: Fiber optic | J764: No | K764: No | L764: No | M764: No | N764: No | O764: No | P764: Month-to-month | Q764: Yes | R764: Electronic check | S764: 70.3 | T764: 208.85 | U764: Yes | V764: =IF(F764<=12,"0-12 Months",IF(F764<=24,"13-24 Months",IF(F764<=48,"25-48 Months","49-72 Months"))) -> 0-12 Months | W764: =IF(S764<=30,"0-30",IF(S764<=60,"31-60",IF(S764<=90,"61-90","91+"))) -> 61-90 | X764: =COUNTIF(G764:O764,"Yes") -> 1
A765: 1266-NZYUI | B765: Female | C765: 0 | D765: Yes | E765: Yes | F765: 72 | G765: Yes | H765: Yes | I765: DSL | J765: Yes | K765: No | L765: Yes | M765: Yes | N765: No | O765: No | P765: Two year | Q765: No | R765: Bank transfer (automatic) | S765: 66.85 | T765: 4758.8 | U765: No | V765: =IF(F765<=12,"0-12 Months",IF(F765<=24,"13-24 Months",IF(F765<=48,"25-48 Months","49-72 Months"))) -> 49-72 Months | W765: =IF(S765<=30,"0-30",IF(S765<=60,"31-60",IF(S765<=90,"61-90","91+"))) -> 61-90 | X765: =COUNTIF(G765:O765,"Yes") -> 5
A766: 7969-FFOWG | B766: Male | C766: 0 | D766: Yes | E766: Yes | F766: 65 | G766: Yes | H766: No | I766: No | J766: No internet service | K766: No internet service | L766: No internet service | M766: No internet service | N766: No internet service | O766: No internet service | P766: Two year | Q766: No | R766: Mailed check | S766: 19.9 | T766: 1292.6 | U766: No | V766: =IF(F766<=12,"0-12 Months",IF(F766<=24,"13-24 Months",IF(F766<=48,"25-48 Months","49-72 Months"))) -> 49-72 Months | W766: =IF(S766<=30,"0-30",IF(S766<=60,"31-60",IF(S766<=90,"61-90","91+"))) -> 0-30 | X766: =COUNTIF(G766:O766,"Yes") -> 1
...

Sheet Service Bundle Analysis
A1: Churn | B1: Yes
A3: Row Labels | B3: Total Customers | C3: Count of customerID | D3: Total Customers | E3: Churn Rate %
A4: 0 | B4: 35 | C4: 35 | D4: =COUNTIF(IBM_Telecom_Customer_Churn_Anal!$X:$X,A4) -> 80 | E4: =B4/D4 -> 0.4375
A5: 1 | B5: 359 | C5: 359 | D5: =COUNTIF(IBM_Telecom_Customer_Churn_Anal!$X:$X,A5) -> 1701 | E5: =B5/D5 -> 0.21105232
A6: 2 | B6: 390 | C6: 390 | D6: =COUNTIF(IBM_Telecom_Customer_Churn_Anal!$X:$X,A6) -> 1188 | E6: =B6/D6 -> 0.32828283
A7: 3 | B7: 352 | C7: 352 | D7: =COUNTIF(IBM_Telecom_Customer_Churn_Anal!$X:$X,A7) -> 965 | E7: =B7/D7 -> 0.36476684
A8: 4 | B8: 289 | C8: 289 | D8: =COUNTIF(IBM_Telecom_Customer_Churn_Anal!$X:$X,A8) -> 922 | E8: =B8/D8 -> 0.31344902
A9: 5 | B9: 232 | C9: 232 | D9: =COUNTIF(IBM_Telecom_Customer_Churn_Anal!$X:$X,A9) -> 908 | E9: =B9/D9 -> 0.25550661
A10: 6 | B10: 152 | C10: 152 | D10: =COUNTIF(IBM_Telecom_Customer_Churn_Anal!$X:$X,A10) -> 676 | E10: =B10/D10 -> 0.22485207
A11: 7 | B11: 49 | C11: 49 | D11: =COUNTIF(IBM_Telecom_Customer_Churn_Anal!$X:$X,A11) -> 395 | E11: =B11/D11 -> 0.12405063
A12: 8 | B12: 11 | C12: 11 | D12: =COUNTIF(IBM_Telecom_Customer_Churn_Anal!$X:$X,A12) -> 208 | E12: =B12/D12 -> 0.052884615
A13: Grand Total | B13: 1869 | C13: 1869 | D13: =SUM(D4:D12) -> 7043

Sheet Business Case Calc
A1: Metric | B1: Value
A2: Total M2M Churners | B2: 1655
A3: Avg Monthly Charge | B3: $64.76
A4: Incentive Cost | B4: $20
A5: Customers Saved (10%) | B5: 166
A6: Revenue Recovered | B6: $10,751
A7: Campaign Cost | B7: $3,320
A8: Net Monthly Gain | B8: $7431
A9: Payback Period | B9: 0.45 Months

Sheet Cohort Analysis
A1: Tenure Group | B1: Churned Customers | C1: Churn Rate %
A2: 0-12 Months | B2: 1037 | C2: 0.4744
A3: 13-24 Months | B3: 294 | C3: 0.2871
A4: 25-48 Months | B4: 325 | C4: 0.2039
A5: 49-72 Months | B5: 213 | C5: 0.0951

Sheet Customer Risk Tier Analysis
A1: Customer Risk Tier Analysis
A3: Risk Tier | B3: Total Customers | C3: Churned Customers | D3: Churn Rate %
A4: High Risk | B4: 2455 | C4: =COUNTIFS('Risk Score'!$I:$I,"High Risk",'Risk Score'!$G:$G,"Yes") -> 1316 | D4: =C4/B4 -> 0.53604888
A5: Low Risk | B5: 2180 | C5: =COUNTIFS('Risk Score'!$I:$I,"Medium Risk",'Risk Score'!$G:$G,"Yes") -> 477 | D5: =C5/B5 -> 0.21880734
A6: Medium Risk | B6: 2408 | C6: =COUNTIFS('Risk Score'!$I:$I,"Low Risk",'Risk Score'!$G:$G,"Yes") -> 76 | D6: =C6/B6 -> 0.031561462
A7: Grand Total | B7: 7043 | C7: =SUM(C4:C6) -> 1869 | D7: =C7/B7 -> 0.26536987
A10: Key Finding: High-risk customers show a churn rate of 53.60%, compared to only 3.49% for low-risk customers. This validates the predictive risk scoring model and helps identify customers likely to churn before they leave.

Sheet Risk Score
A1: customerID | B1: Contract | C1: tenure | D1: TenureGroup | E1: InternetService | F1: PaymentMethod | G1: Churn | H1: Risk Points | I1: Risk Tier
A2: 7590-VHVEG | B2: Month-to-month | C2: 1 | D2: =IF(C2<=12,"0-12 Months",IF(C2<=24,"13-24 Months",IF(C2<=48,"25-48 Months","49-72 Months"))) -> 0-12 Months | E2: DSL | F2: Electronic check | G2: No | H2: =IF(B2="Month-to-month",2,0)+IF(E2="Fiber optic",2,0)+IF(F2="Electronic check",1,0)+IF(D2="0-12 Months",1,0) -> 4 | I2: =IF(H2>=4,"High Risk",IF(H2>=2,"Medium Risk","Low Risk")) -> High Risk
A3: 5575-GNVDE | B3: One year | C3: 34 | D3: =IF(C3<=12,"0-12 Months",IF(C3<=24,"13-24 Months",IF(C3<=48,"25-48 Months","49-72 Months"))) -> 25-48 Months | E3: DSL | F3: Mailed check | G3: No | H3: =IF(B3="Month-to-month",2,0)+IF(E3="Fiber optic",2,0)+IF(F3="Electronic check",1,0)+IF(D3="0-12 Months",1,0) -> 0 | I3: =IF(H3>=4,"High Risk",IF(H3>=2,"Medium Risk","Low Risk")) -> Low Risk
A4: 3668-QPYBK | B4: Month-to-month | C4: 2 | D4: =IF(C4<=12,"0-12 Months",IF(C4<=24,"13-24 Months",IF(C4<=48,"25-48 Months","49-72 Months"))) -> 0-12 Months | E4: DSL | F4: Mailed check | G4: Yes | H4: =IF(B4="Month-to-month",2,0)+IF(E4="Fiber optic",2,0)+IF(F4="Electronic check",1,0)+IF(D4="0-12 Months",1,0) -> 3 | I4: =IF(H4>=4,"High Risk",IF(H4>=2,"Medium Risk","Low Risk")) -> Medium Risk
A5: 7795-CFOCW | B5: One year | C5: 45 | D5: =IF(C5<=12,"0-12 Months",IF(C5<=24,"13-24 Months",IF(C5<=48,"25-48 Months","49-72 Months"))) -> 25-48 Months | E5: DSL | F5: Bank transfer (automatic) | G5: No | H5: =IF(B5="Month-to-month",2,0)+IF(E5="Fiber optic",2,0)+IF(F5="Electronic check",1,0)+IF(D5="0-12 Months",1,0) -> 0 | I5: =IF(H5>=4,"High Risk",IF(H5>=2,"Medium Risk","Low Risk")) -> Low Risk
A6: 9237-HQITU | B6: Month-to-month | C6: 2 | D6: =IF(C6<=12,"0-12 Months",IF(C6<=24,"13-24 Months",IF(C6<=48,"25-48 Months","49-72 Months"))) -> 0-12 Months | E6: Fiber optic | F6: Electronic check | G6: Yes | H6: =IF(B6="Month-to-month",2,0)+IF(E6="Fiber optic",2,0)+IF(F6="Electronic check",1,0)+IF(D6="0-12 Months",1,0) -> 6 | I6: =IF(H6>=4,"High Risk",IF(H6>=2,"Medium Risk","Low Risk")) -> High Risk
A7: 9305-CDSKC | B7: Month-to-month | C7: 8 | D7: =IF(C7<=12,"0-12 Months",IF(C7<=24,"13-24 Months",IF(C7<=48,"25-48 Months","49-72 Months"))) -> 0-12 Months | E7: Fiber optic | F7: Electronic check | G7: Yes | H7: =IF(B7="Month-to-month",2,0)+IF(E7="Fiber optic",2,0)+IF(F7="Electronic check",1,0)+IF(D7="0-12 Months",1,0) -> 6 | I7: =IF(H7>=4,"High Risk",IF(H7>=2,"Medium Risk","Low Risk")) -> High Risk
A8: 1452-KIOVK | B8: Month-to-month | C8: 22 | D8: =IF(C8<=12,"0-12 Months",IF(C8<=24,"13-24 Months",IF(C8<=48,"25-48 Months","49-72 Months"))) -> 13-24 Months | E8: Fiber optic | F8: Credit card (automatic) | G8: No | H8: =IF(B8="Month-to-month",2,0)+IF(E8="Fiber optic",2,0)+IF(F8="Electronic check",1,0)+IF(D8="0-12 Months",1,0) -> 4 | I8: =IF(H8>=4,"High Risk",IF(H8>=2,"Medium Risk","Low Risk")) -> High Risk
A9: 6713-OKOMC | B9: Month-to-month | C9: 10 | D9: =IF(C9<=12,"0-12 Months",IF(C9<=24,"13-24 Months",IF(C9<=48,"25-48 Months","49-72 Months"))) -> 0-12 Months | E9: DSL | F9: Mailed check | G9: No | H9: =IF(B9="Month-to-month",2,0)+IF(E9="Fiber optic",2,0)+IF(F9="Electronic check",1,0)+IF(D9="0-12 Months",1,0) -> 3 | I9: =IF(H9>=4,"High Risk",IF(H9>=2,"Medium Risk","Low Risk")) -> Medium Risk
A10: 7892-POOKP | B10: Month-to-month | C10: 28 | D10: =IF(C10<=12,"0-12 Months",IF(C10<=24,"13-24 Months",IF(C10<=48,"25-48 Months","49-72 Months"))) -> 25-48 Months | E10: Fiber optic | F10: Electronic check | G10: Yes | H10: =IF(B10="Month-to-month",2,0)+IF(E10="Fiber optic",2,0)+IF(F10="Electronic check",1,0)+IF(D10="0-12 Months",1,0) -> 5 | I10: =IF(H10>=4,"High Risk",IF(H10>=2,"Medium Risk","Low Risk")) -> High Risk
A11: 6388-TABGU | B11: One year | C11: 62 | D11: =IF(C11<=12,"0-12 Months",IF(C11<=24,"13-24 Months",IF(C11<=48,"25-48 Months","49-72 Months"))) -> 49-72 Months | E11: DSL | F11: Bank transfer (automatic) | G11: No | H11: =IF(B11="Month-to-month",2,0)+IF(E11="Fiber optic",2,0)+IF(F11="Electronic check",1,0)+IF(D11="0-12 Months",1,0) -> 0 | I11: =IF(H11>=4,"High Risk",IF(H11>=2,"Medium Risk","Low Risk")) -> Low Risk
A12: 9763-GRSKD | B12: Month-to-month | C12: 13 | D12: =IF(C12<=12,"0-12 Months",IF(C12<=24,"13-24 Months",IF(C12<=48,"25-48 Months","49-72 Months"))) -> 13-24 Months | E12: DSL | F12: Mailed check | G12: No | H12: =IF(B12="Month-to-month",2,0)+IF(E12="Fiber optic",2,0)+IF(F12="Electronic check",1,0)+IF(D12="0-12 Months",1,0) -> 2 | I12: =IF(H12>=4,"High Risk",IF(H12>=2,"Medium Risk","Low Risk")) -> Medium Risk
A13: 7469-LKBCI | B13: Two year | C13: 16 | D13: =IF(C13<=12,"0-12 Months",IF(C13<=24,"13-24 Months",IF(C13<=48,"25-48 Months","49-72 Months"))) -> 13-24 Months | E13: No | F13: Credit card (automatic) | G13: No | H13: =IF(B13="Month-to-month",2,0)+IF(E13="Fiber optic",2,0)+IF(F13="Electronic check",1,0)+IF(D13="0-12 Months",1,0) -> 0 | I13: =IF(H13>=4,"High Risk",IF(H13>=2,"Medium Risk","Low Risk")) -> Low Risk
... A7044: 3186-AJIEK | B7044: Two year | C7044: 66 | D7044: =IF(C7044<=12,"0-12 Months",IF(C7044<=24,"13-24 Months",IF(C7044<=48,"25-48 Months","49-72 Months"))) -> 49-72 Months | E7044: Fiber optic | F7044: Bank transfer (automatic) | G7044: No | H7044: =IF(B7044="Month-to-month",2,0)+IF(E7044="Fiber optic",2,0)+IF(F7044="Electronic check",1,0)+IF(D7044="0-12 Months",1,0) -> 2 | I7044: =IF(H7044>=4,"High Risk",IF(H7044>=2,"Medium Risk","Low Risk")) -> Medium Risk

Sheet Churn_Overview
A3: Row Labels | B3: Count of customerID
A4: No | B4: 5174
A5: Yes | B5: 1869
A6: Grand Total | B6: 7043

Sheet Contract_vs_Churn
A3: Count of customerID | B3: Column Labels
A4: Row Labels | B4: No | C4: Yes | D4: Grand Total
A5: Month-to-month | B5: 2220 | C5: 1655 | D5: 3875
A6: One year | B6: 1307 | C6: 166 | D6: 1473
A7: Two year | B7: 1647 | C7: 48 | D7: 1695
A8: Grand Total | B8: 5174 | C8: 1869 | D8: 7043

Sheet Payment_vs_Churn
A3: Count of customerID | B3: Column Labels
A4: Row Labels | B4: No | C4: Yes | D4: Grand Total
A5: Bank transfer (automatic) | B5: 1286 | C5: 258 | D5: 1544
A6: Credit card (automatic) | B6: 1290 | C6: 232 | D6: 1522
A7: Electronic check | B7: 1294 | C7: 1071 | D7: 2365
A8: Mailed check | B8: 1304 | C8: 308 | D8: 1612
A9: Grand Total | B9: 5174 | C9: 1869 | D9: 7043

Sheet Internet_vs_Churn
A3: Count of customerID | B3: Column Labels
A4: Row Labels | B4: No | C4: Yes | D4: Grand Total
A5: DSL | B5: 1962 | C5: 459 | D5: 2421
A6: Fiber optic | B6: 1799 | C6: 1297 | D6: 3096
A7: No | B7: 1413 | C7: 113 | D7: 1526
A8: Grand Total | B8: 5174 | C8: 1869 | D8: 7043

Sheet Contract_Internet_vs_Churn
A3: Count of customerID | B3: Column Labels
A4: Row Labels | B4: No | C4: Yes | D4: Grand Total
A5: Month-to-month | B5: 2220 | C5: 1655 | D5: 3875
A6: DSL | B6: 829 | C6: 394 | D6: 1223
A7: Fiber optic | B7: 966 | C7: 1162 | D7: 2128
A8: No | B8: 425 | C8: 99 | D8: 524
A9: One year | B9: 1307 | C9: 166 | D9: 1473
A10: DSL | B10: 517 | C10: 53 | D10: 570
A11: Fiber optic | B11: 435 | C11: 104 | D11: 539
A12: No | B12: 355 | C12: 9 | D12: 364
A13: Two year | B13: 1647 | C13: 48 | D13: 1695
A14: DSL | B14: 616 | C14: 12 | D14: 628
A15: Fiber optic | B15: 398 | C15: 31 | D15: 429
A16: No | B16: 633 | C16: 5 | D16: 638
A17: Grand Total | B17: 5174 | C17: 1869 | D17: 7043

Sheet Tenure_vs_Churn
A3: Count of customerID | B3: Column Labels
A4: Row Labels | B4: No | C4: Yes | D4: Grand Total
A5: 0 | B5: 11 | D5: 11
A6: 1 | B6: 233 | C6: 380 | D6: 613
A7: 2 | B7: 115 | C7: 123 | D7: 238
A8: 3 | B8: 106 | C8: 94 | D8: 200
A9: 4 | B9: 93 | C9: 83 | D9: 176
A10: 5 | B10: 69 | C10: 64 | D10: 133
A11: 6 | B11: 70 | C11: 40 | D11: 110
A12: 7 | B12: 80 | C12: 51 | D12: 131
A13: 8 | B13: 81 | C13: 42 | D13: 123
A14: 9 | B14: 73 | C14: 46 | D14: 119
A15: 10 | B15: 71 | C15: 45 | D15: 116
A16: 11 | B16: 68 | C16: 31 | D16: 99
A17: 12 | B17: 79 | C17: 38 | D17: 117
... A77: 72 | B77: 356 | C77: 6 | D77: 362
A78: Grand Total | B78: 5174 | C78: 1869 | D78: 7043

Sheet TenureGroup_vs_Churn
A3: Count of customerID | B3: Column Labels
A4: Row Labels | B4: No | C4: Yes | D4: Grand Total
A5: 0-12 Months | B5: 1149 | C5: 1037 | D5: 2186
A6: 13-24 Months | B6: 730 | C6: 294 | D6: 1024
A7: 25-48 Months | B7: 1269 | C7: 325 | D7: 1594
A8: 49-72 Months | B8: 2026 | C8: 213 | D8: 2239
A9: Grand Total | B9: 5174 | C9: 1869 | D9: 7043

Sheet Monthly Charge 
A3: Count of customerID | B3: Column Labels
A4: Row Labels | B4: No | C4: Yes | D4: Grand Total
A5: 18.25 | B5: 1 | D5: 1
A6: 18.4 | B6: 1 | D6: 1
A7: 18.55 | B7: 1 | D7: 1
A8: 18.7 | B8: 2 | D8: 2
A9: 18.75 | B9: 1 | D9: 1
A10: 18.8 | B10: 7 | D10: 7
A11: 18.85 | B11: 4 | C11: 1 | D11: 5
A12: 18.9 | B12: 2 | D12: 2
A13: 18.95 | B13: 5 | C13: 1 | D13: 6
A14: 19 | B14: 6 | C14: 1 | D14: 7
A15: 19.05 | B15: 9 | D15: 9
A16: 19.1 | B16: 11 | C16: 1 | D16: 12
A17: 19.15 | B17: 11 | D17: 11
A18: 19.2 | B18: 17 | D18: 17
A19: 19.25 | B19: 15 | C19: 3 | D19: 18
A20: 19.3 | B20: 21 | C20: 3 | D20: 24
A21: 19.35 | B21: 23 | C21: 2 | D21: 25
A22: 19.4 | B22: 27 | C22: 4 | D22: 31
A23: 19.45 | B23: 25 | C23: 3 | D23: 28
A24: 19.5 | B24: 29 | C24: 3 | D24: 32
A25: 19.55 | B25: 38 | C25: 2 | D25: 40
A26: 19.6 | B26: 33 | C26: 4 | D26: 37
A27: 19.65 | B27: 39 | C27: 4 | D27: 43
A28: 19.7 | B28: 41 | C28: 2 | D28: 43
A29: 19.75 | B29: 33 | C29: 6 | D29: 39
A30: 19.8 | B30: 35 | C30: 3 | D30: 38
... A42: 20.4 | B42: 28 | C42: 2 | D42: 30
A43: 20.45 | B43: 31 | D43: 31
A44: 20.5 | B44: 25 | C44: 3 | D44: 28
A45: 20.55 | B45: 24 | C45: 3 | D45: 27
A46: 20.6 | B46: 14 | C46: 1 | D46: 15
A47: 20.65 | B47: 22 | C47: 1 | D47: 23
A48: 20.7 | B48: 13 | D48: 13
A49: 20.75 | B49: 17 | D49: 17
A50: 20.8 | B50: 7 | C50: 1 | D50: 8
A51: 20.85 | B51: 14 | C51: 1 | D51: 15
A52: 20.9 | B52: 8 | C52: 2 | D52: 10
A53: 20.95 | B53: 6 | C53: 2 | D53: 8
...

Sheet Monthly Charge Group
A3: Count of customerID | B3: Column Labels
A4: Row Labels | B4: No | C4: Yes | D4: Grand Total
A5: 0-30 | B5: 1491 | C5: 162 | D5: 1653
A6: 31-60 | B6: 937 | C6: 328 | D6: 1265
A7: 61-90 | B7: 1577 | C7: 809 | D7: 2386
A8: 91+ | B8: 1169 | C8: 570 | D8: 1739
A9: Grand Total | B9: 5174 | C9: 1869 | D9: 7043

Sheet SeniorCitizen_vs_Churn
A3: Count of customerID | B3: Column Labels
A4: Row Labels | B4: No | C4: Yes | D4: Grand Total
A5: 0 | B5: 4508 | C5: 1393 | D5: 5901
A6: 1 | B6: 666 | C6: 476 | D6: 1142
A7: Grand Total | B7: 5174 | C7: 1869 | D7: 7043

Sheet TechSupport_vs_Churn
A3: Count of customerID | B3: Column Labels
A4: Row Labels | B4: No | C4: Yes | D4: Grand Total
A5: No | B5: 2027 | C5: 1446 | D5: 3473
A6: No internet service | B6: 1413 | C6: 113 | D6: 1526
A7: Yes | B7: 1734 | C7: 310 | D7: 2044
A8: Grand Total | B8: 5174 | C8: 1869 | D8: 7043

Sheet Partner_vs_Churn
A3: Count of customerID | B3: Column Labels
A4: Row Labels | B4: No | C4: Yes | D4: Grand Total
A5: No | B5: 2441 | C5: 1200 | D5: 3641
A6: Yes | B6: 2733 | C6: 669 | D6: 3402
A7: Grand Total | B7: 5174 | C7: 1869 | D7: 7043

Sheet Dependents_vs_Churn
A3: Count of customerID | B3: Column Labels
A4: Row Labels | B4: No | C4: Yes | D4: Grand Total
A5: No | B5: 3390 | C5: 1543 | D5: 4933
A6: Yes | B6: 1784 | C6: 326 | D6: 2110
A7: Grand Total | B7: 5174 | C7: 1869 | D7: 7043

Sheet Gender_vs_Churn
A3: Count of customerID | B3: Column Labels
A4: Row Labels | B4: No | C4: Yes | D4: Grand Total
A5: Female | B5: 2549 | C5: 939 | D5: 3488
A6: Male | B6: 2625 | C6: 930 | D6: 3555
A7: Grand Total | B7: 5174 | C7: 1869 | D7: 7043

Sheet OnlineSecurity_vs_Churn
A3: Count of customerID | B3: Column Labels
A4: Row Labels | B4: No | C4: Yes | D4: Grand Total
A5: No | B5: 2037 | C5: 1461 | D5: 3498
A6: No internet service | B6: 1413 | C6: 113 | D6: 1526
A7: Yes | B7: 1724 | C7: 295 | D7: 2019
A8: Grand Total | B8: 5174 | C8: 1869 | D8: 7043

Sheet PaperlessBilling_vs_Churn
A3: Count of customerID | B3: Column Labels
A4: Row Labels | B4: No | C4: Yes | D4: Grand Total
A5: No | B5: 2403 | C5: 469 | D5: 2872
A6: Yes | B6: 2771 | C6: 1400 | D6: 4171
A7: Grand Total | B7: 5174 | C7: 1869 | D7: 7043
